<?xml version="1.0"?>

<robot name="x500_frame_fpv_drone" xmlns:xacro="http://ros.org/wiki/xacro">
  
  <xacro:arg name="is_ignition" default="true"/>
  <xacro:arg name="is_sim" default="true"/>


  <material name="dark_gray">
    <color rgba="0.2 0.2 0.2 1.0"/>
  </material>

  <material name="propeller_black">
    <color rgba="0.05 0.05 0.05 1.0"/>
  </material>

  <link name="base_footprint"/>

  <link name="base_link">
    <inertial>
      <origin xyz="-0.00532317762341794 3.58817647790888E-05 -0.0816191136989204" rpy="0 0 0" />
      <mass value="0.466180774385218" />
      <inertia ixx="0.000277753237068403" ixy="2.6626826811937E-06" ixz="-1.53978574160421E-07"
               iyy="0.000452011735309793" iyz="2.04117851091923E-08"
               izz="0.000577089151095544" />
    </inertial>
    <visual>
      <origin xyz="0 0 0" rpy="0 0 0" />
      <geometry>
        <mesh
          filename="package://x500_frame_fpv_drone/meshes/base_link.STL" />
      </geometry>
      <material name="dark_gray"/>
    </visual>
    <collision>
      <origin xyz="0 0 0" rpy="0 0 0" />
      <geometry>
        <mesh
          filename="package://x500_frame_fpv_drone/meshes/base_link.STL" />
      </geometry>
    </collision>
  </link>

  <joint name="base_joint" type="fixed">
    <parent link="base_footprint"/>
    <child link="base_link" />
    <origin xyz="0 0 0.25" rpy="0 0 0"/>
  </joint>


  <link name="prop_link_1">
    <inertial>
      <origin xyz="4.3758E-08 2.9987E-10 -0.0042202" rpy="0 0 0" />
      <mass value="0.012411" />
      <inertia ixx="1.4162E-06" ixy="5.1216E-06" ixz="-7.7441E-13"
               iyy="3.8656E-05" iyz="-1.051E-13"
               izz="3.9969E-05" />
    </inertial>
    <visual>
      <origin xyz="0 0 0" rpy="0 0 0" />
      <geometry>
        <mesh
          filename="package://x500_frame_fpv_drone/meshes/prop_link_1.STL" />
      </geometry>
      <material name="propeller_black"/>
    </visual>
    <collision>
      <origin xyz="0 0 0" rpy="0 0 0" />
      <geometry>
        <mesh
          filename="package://x500_frame_fpv_drone/meshes/prop_link_1.STL" />
      </geometry>
    </collision>
  </link>

  <joint name="prop_joint_1" type="continuous">
    <origin xyz="-0.1805 0.1805 0.03445" rpy="0 0 0" />
    <parent link="base_link" />
    <child link="prop_link_1" />
    <axis xyz="0 0 1" />
  </joint>

  <link name="prop_link_2">
    <inertial>
      <origin xyz="-4.1254E-08 -1.956E-08 -0.0042202" rpy="0 0 0" />
      <mass value="0.012411" />
      <inertia ixx="3.1266E-06" ixy="-9.3275E-06" ixz="5.4797E-13"
               iyy="3.6946E-05" iyz="3.2445E-13"
               izz="3.9969E-05" />
    </inertial>
    <visual>
      <origin xyz="0 0 0" rpy="0 0 0" />
      <geometry>
        <mesh
          filename="package://x500_frame_fpv_drone/meshes/prop_link_2.STL" />
      </geometry>
      <material name="propeller_black"/>
    </visual>
    <collision>
      <origin xyz="0 0 0" rpy="0 0 0" />
      <geometry>
        <mesh
          filename="package://x500_frame_fpv_drone/meshes/prop_link_2.STL" />
      </geometry>
    </collision>
  </link>

  <joint name="prop_joint_2" type="continuous">
    <origin xyz="-0.1805 -0.1805 0.03445" rpy="0 0 0" />
    <parent link="base_link" />
    <child link="prop_link_2" />
    <axis xyz="0 0 1" />
  </joint>

  <link name="prop_link_3">
    <inertial>
      <origin xyz="1.25091661473675E-08 -5.16898481794925E-08 -0.00422024191479586" rpy="0 0 0" />
      <mass value="0.0124110336424998" />
      <inertia ixx="3.85373088743405E-05" ixy="5.53668654270368E-06" ixz="-3.16915858706439E-13"
               iyy="1.53536747930414E-06" iyz="1.10653710863156E-12"
               izz="3.99685950827954E-05" />
    </inertial>
    <visual>
      <origin xyz="0 0 0" rpy="0 0 0" />
      <geometry>
        <mesh
          filename="package://x500_frame_fpv_drone/meshes/prop_link_3.STL" />
      </geometry>
      <material name="propeller_black"/>
    </visual>
    <collision>
      <origin xyz="0 0 0" rpy="0 0 0" />
      <geometry>
        <mesh
          filename="package://x500_frame_fpv_drone/meshes/prop_link_3.STL" />
      </geometry>
    </collision>
  </link>

  <joint name="prop_joint_3" type="continuous">
    <origin xyz="0.1805 0.1805 0.03445" rpy="0 0 0" />
    <parent link="base_link" />
    <child link="prop_link_3" />
    <axis xyz="0 0 1" />
  </joint>


  <link name="prop_link_4">
    <inertial>
      <origin xyz="2.9622E-08 -4.1692E-08 -0.0042202" rpy="0 0 0" />
      <mass value="0.012411" />
      <inertia ixx="3.1858E-05" ixy="1.527E-05" ixz="-5.0198E-13"
               iyy="8.2142E-06" iyz="6.8439E-13"
               izz="3.9969E-05" />
    </inertial>
    <visual>
      <origin xyz="0 0 0" rpy="0 0 0" />
      <geometry>
        <mesh
          filename="package://x500_frame_fpv_drone/meshes/prop_link_4.STL" />
      </geometry>
      <material name="propeller_black"/>
    </visual>
    <collision>
      <origin xyz="0 0 0" rpy="0 0 0" />
      <geometry>
        <mesh
          filename="package://x500_frame_fpv_drone/meshes/prop_link_4.STL" />
      </geometry>
    </collision>
  </link>

  <joint name="prop_joint_4" type="continuous">
    <origin xyz="0.1805 -0.1805 0.03445" rpy="0 0 0" />
    <parent link="base_link" />
    <child link="prop_link_4" />
    <axis xyz="0 0 1" />
  </joint>
</robot>